Workbook

Sheet Plan_Resumen
A1: Plan hacia US$ 1M de utilidad anual - resumen de escenarios
A2: Todo son formulas. Cambia los supuestos en Plan_Supuestos. La utilidad es antes de impuestos salvo que pongas una tasa. Canales propios (Shopify + WhatsApp).
A4: Resultado | B4: Conservador | C4: Base | D4: Ambicioso
A5: Gasto Meta al mes 24 (S/ por mes) | B5: =Plan_Conservador!Y7 -> 52843.173 | C5: =Plan_Base!Y7 -> 121971.13 | D5: =Plan_Ambicioso!Y7 -> 224023.12
A6: CAC al mes 24 (S/) | B6: =Plan_Conservador!Y9 -> 128.92008 | C6: =Plan_Base!Y9 -> 100.76932 | D6: =Plan_Ambicioso!Y9 -> 69.480805
A7: Pedidos nuevos por dia al mes 24 | B7: =Plan_Conservador!Y13 -> 15.029335 | C7: =Plan_Base!Y13 -> 46.398642 | D7: =Plan_Ambicioso!Y13 -> 128.96979
A8: Utilidad neta del mes 12 (S/) | B8: =Plan_Conservador!M32 -> 14614.332 | C8: =Plan_Base!M32 -> 63144.127 | D8: =Plan_Ambicioso!M32 -> 167097.6
A9: Utilidad neta del mes 24 (S/) | B9: =Plan_Conservador!Y32 -> 31686.001 | C9: =Plan_Base!Y32 -> 204344.81 | D9: =Plan_Ambicioso!Y32 -> 808547.35
A10: Utilidad de los ultimos 12 meses, mes 13 a 24 (US$) | B10: =Plan_Conservador!Y34/Plan_Supuestos!$B$13 -> 81761.522 | C10: =Plan_Base!Y34/Plan_Supuestos!$B$13 -> 451936.41 | D10: =Plan_Ambicioso!Y34/Plan_Supuestos!$B$13 -> 1554638.4
A11: Run-rate anual al mes 24 (US$) | B11: =Plan_Conservador!Y36 -> 108637.72 | C11: =Plan_Base!Y36 -> 700610.77 | D11: =Plan_Ambicioso!Y36 -> 2772162.4
A12: Utilidad acumulada en 24 meses (US$) | B12: =Plan_Conservador!Y33/Plan_Supuestos!$B$13 -> 107573.48 | C12: =Plan_Base!Y33/Plan_Supuestos!$B$13 -> 561797.75 | D12: =Plan_Ambicioso!Y33/Plan_Supuestos!$B$13 -> 1812790.2
A13: Primer mes con run-rate anual >= meta | B13: =IFERROR(MATCH(1,Plan_Conservador!B37:Y37,0),"no en 24 meses") -> no en 24 meses | C13: =IFERROR(MATCH(1,Plan_Base!B37:Y37,0),"no en 24 meses") -> no en 24 meses | D13: =IFERROR(MATCH(1,Plan_Ambicioso!B37:Y37,0),"no en 24 meses") -> 16
A14: Necesidad maxima de caja (S/) | B14: =-MIN(0,MIN(Plan_Conservador!B42:Y42)) -> 0 | C14: =-MIN(0,MIN(Plan_Base!B42:Y42)) -> 0 | D14: =-MIN(0,MIN(Plan_Ambicioso!B42:Y42)) -> 0
A16: Lectura: la meta es US$ 1M de utilidad al año. "Run-rate" = utilidad del mes x 12. Si el escenario no llega, la fila "Primer mes" dice "no en 24 meses".
A18: Que comprar en el proximo lote (escenario Base)
A19: Producto | B19: Demanda meses 5 a 10 (Mar-Ago 2027) | C19: Con colchon | D19: Stock actual | E19: A comprar | F19: Costo unitario puesto en Lima (S/) | G19: Capital (S/)
A20: Purificadores Nativo + Vivo | B20: =SUM(Plan_Base!F43:K43) -> 1494.7985 | C20: =B20*(1+$B$27) -> 1793.7582 | D20: 450 | E20: =MAX(0,C20-D20) -> 1343.7582 | F20: =Costo_Lima!F35 -> 22.419911 | G20: =E20*F20 -> 30126.939
A21: Repuestos de caño | B21: =SUM(Plan_Base!F44:K44) -> 1953.0325 | C21: =B21*(1+$B$27) -> 2343.6389 | D21: 600 | E21: =MAX(0,C21-D21) -> 1743.6389 | F21: =Costo_Lima!F36 -> 2.5165207 | G21: =E21*F21 -> 4387.9035
A22: Piezas Ritual | B22: =SUM(Plan_Base!F45:K45) -> 278.31055 | C22: =B22*(1+$B$27) -> 333.97266 | D22: 0 | E22: =MAX(0,C22-D22) -> 333.97266 | F22: =Costo_Lima!F37 -> 16.242997 | G22: =E22*F22 -> 5424.7169
A23: Bidon 22 L | B23: =SUM(Plan_Base!F46:K46) -> 146.11764 | C23: =B23*(1+$B$27) -> 175.34117 | D23: 804 | E23: =MAX(0,C23-D23) -> 0 | F23: =Contenedor2!F71 -> 47.548951 | G23: =E23*F23 -> 0
A24: Bidon 16 L | B24: =SUM(Plan_Base!F47:K47) -> 94.632956 | C24: =B24*(1+$B$27) -> 113.55955 | D24: 804 | E24: =MAX(0,C24-D24) -> 0 | F24: =Contenedor2!F72 -> 39.841592 | G24: =E24*F24 -> 0
A25: elvo· Cero | B25: =SUM(Plan_Base!F48:K48) -> 73.745846 | C25: =B25*(1+$B$27) -> 88.495016 | D25: 100 | E25: =MAX(0,C25-D25) -> 0 | F25: =Contenedor2!F74 -> 635.12307 | G25: =E25*F25 -> 0
A26: Total capital del lote | G26: =SUM(G20:G25) -> 39939.559
A27: Colchon sobre la demanda | B27: 0.2
A28: Stock actual: 450 purificadores y 600 repuestos (usuario); bidones, Cero y kits son los del contenedor que llega el 25-oct. Los bidones y el Cero ya estan comprados: cuentan como stock.
A29: La demanda de purificadores y repuestos sale de los pedidos del escenario Base; el tiempo de importacion es de ~4.5 meses, por eso este lote llega para marzo de 2027.

Sheet Plan_Supuestos
A1: Plan hacia US$ 1M de utilidad - supuestos (canales propios: Shopify y WhatsApp/YaVendio)
A2: Azul = supuesto editable; amarillo = el mas incierto. Verde = viene de las otras hojas. Los marketplaces van en otro analisis.
A4: General (igual en los tres escenarios) | B4: Valor | C4: Nota
A5: Pedidos nuevos por dia hoy | B5: 4.5 | C5: Sep-oct 2026: ~222 pedidos en 49 dias entre Shopify y YaVendio.
A6: Gasto Meta mensual hoy (S/) | B6: 9000 | C6: Sep-oct 2026: S/ 14.1k en 49 dias.
A7: Pedidos de base historica que generan recompra el primer año | B7: 60 | C7: SUPUESTO: clientes anteriores que aun renuevan.
A8: Pedidos de Lima (% del total) | B8: 0.75 | C8: Lima 80% de entrega y provincia con seña: el promedio de 85% implica ~25% provincia.
A9: Costos fijos al mes (S/) | B9: 15000 | C9: SUPUESTO: equipo, software, oficina. REEMPLAZAR con tus costos reales.
A10: Costo variable por pedido (S/) | B10: 8 | C10: SUPUESTO: atencion al cliente, operaciones, facturacion.
A11: Meses de cobertura de inventario | B11: 5 | C11: Tiempo de importacion: ~4.5 meses.
A12: Impuesto a la renta (0 = utilidad antes de impuestos) | B12: 0 | C12: Confirmar con tu contador.
A13: Tipo de cambio | B13: =Supuestos!B5 -> 3.5
A14: Meta de utilidad anual (US$) | B14: 1000000
A16: Escenarios | B16: Conservador | C16: Base | D16: Ambicioso | E16: Nota
A17: CAC inicial (S/ por pedido nuevo) | B17: 80 | C17: 65 | D17: 55 | E17: Real: sep S/ 54, oct S/ 81, promedio S/ 64.
A18: Elasticidad del CAC al gasto | B18: 0.35 | C18: 0.25 | D18: 0.15 | E18: Si el gasto se duplica, el CAC sube 2^e - 1 (e = 0.25: +19%). SUPUESTO clave.
A19: Crecimiento mensual del gasto en Meta | B19: 0.08 | C19: 0.12 | D19: 0.15
A20: Tope de gasto mensual (S/) | B20: 150000 | C20: 250000 | D20: 400000
A21: Mejora mensual del CAC por optimizacion | B21: 0.005 | C21: 0.01 | D21: 0.015 | E21: Mejores anuncios, seña, confirmacion de pedido.
A22: Tope de la mejora acumulada del CAC | B22: 0.15 | C22: 0.2 | D22: 0.25
A23: Pedidos organicos (% de los pagados) | B23: 0.1 | C23: 0.15 | D23: 0.2 | E23: Referidos, busqueda, recontacto.
A24: Recompra (% de los pedidos nuevos de hace 12 meses) | B24: 0.08 | C24: 0.12 | D24: 0.16 | E24: Repuestos de nucleo.
A25: Participacion del Cero en el mes 12 (% de pedidos) | B25: 0.04 | C25: 0.06 | D25: 0.08 | E25: SUPUESTO: depende de poder vender un producto de S/ 2,299 en WhatsApp.
A26: Mejora de entrega en Lima a los 6 meses (puntos) | B26: 0 | C26: 0.05 | D26: 0.1 | E26: Seña en Lima, confirmacion 24 h antes, The Hub.
A29: Producto | B29: Utilidad antes de publicidad Lima (S/) | C29: Utilidad antes de publicidad provincia (S/) | D29: Utilidad mezclada (S/) | E29: Margen por pedido entregado en Lima (S/) | F29: Costo de producto por pedido (S/) | G29: Mezcla de pedidos: mes 1 | H29: Mezcla de pedidos: mes 12 | I29: Repuestos de caño por pedido | J29: Piezas Ritual por pedido | K29: Factor de CAC vs Nativo | L29: Utilidad despues de publicidad (S/) | M29: Retorno por S/ 1 de publicidad
A30: Nativo (mezcla de planes) | B30: =$B$39*Resumen!C5+$B$40*Resumen!C6+$B$41*Resumen!C7 -> 194.50275 | C30: =$B$39*Resumen!F5+$B$40*Resumen!F6+$B$41*Resumen!F7 -> 258.12843 | D30: =$B$8*B30+(1-$B$8)*C30 -> 210.40917 | E30: =(B30+Supuestos!$B$16+Supuestos!$B$18)/Supuestos!$B$7 -> 263.12843 | F30: =-($B$39*Desglose!B15+$B$40*Desglose!C15+$B$41*Desglose!D15) -> 25.691388 | G30: =1-SUM(G31:G35) -> 0.82 | H30: Resto | I30: =$B$40*1+$B$41*3 -> 1.3 | J30: 0 | K30: 1 | L30: =D30-K30*$C$17 -> 145.40917 | M30: =IF(K30>0,D30/(K30*$C$17),"") -> 3.2370641
A31: Vivo 3 años | B31: =Resumen!C9 -> 126.45455 | C31: =Resumen!F9 -> 173.06819 | D31: =$B$8*B31+(1-$B$8)*C31 -> 138.10796 | E31: =(B31+Supuestos!$B$16+Supuestos!$B$18)/Supuestos!$B$7 -> 178.06819 | F31: =-Desglose!F15 -> 24.936432 | G31: 0.08 | H31: 0.05 | I31: 1 | J31: 0 | K31: 1 | L31: =D31-K31*$C$17 -> 73.107959 | M31: =IF(K31>0,D31/(K31*$C$17),"") -> 2.1247378
A32: Bidon 22 L | B32: =Contenedor2!B89 -> 88.749631 | C32: =Contenedor2!B89 -> 88.749631 | D32: =$B$8*B32+(1-$B$8)*C32 -> 88.749631 | E32: =(B32+Supuestos!$B$16+Supuestos!$B$18)/Supuestos!$B$7 -> 130.93704 | F32: =-Contenedor2!B82 -> 47.548951 | G32: 0.05 | H32: 0.1 | I32: 0 | J32: 0 | K32: 0.5 | L32: =D32-K32*$C$17 -> 56.249631 | M32: =IF(K32>0,D32/(K32*$C$17),"") -> 2.7307579
A33: Bidon 16 L | B33: =Contenedor2!C89 -> 55.685713 | C33: =Contenedor2!C89 -> 55.685713 | D33: =$B$8*B33+(1-$B$8)*C33 -> 55.685713 | E33: =(B33+Supuestos!$B$16+Supuestos!$B$18)/Supuestos!$B$7 -> 89.607141 | F33: =-Contenedor2!C82 -> 39.841592 | G33: 0.04 | H33: 0.06 | I33: 0 | J33: 0 | K33: 0.5 | L33: =D33-K33*$C$17 -> 23.185713 | M33: =IF(K33>0,D33/(K33*$C$17),"") -> 1.7134065
A34: elvo· Cero | B34: =Contenedor2!E89 -> 905.08895 | C34: =Contenedor2!E89 -> 905.08895 | D34: =$B$8*B34+(1-$B$8)*C34 -> 905.08895 | E34: =(B34+Supuestos!$B$16+Supuestos!$B$18)/Supuestos!$B$7 -> 1151.3612 | F34: =-Contenedor2!E82 -> 635.12307 | G34: 0.01 | H34: Segun escenario | I34: 0 | J34: 0 | K34: 2.5 | L34: =D34-K34*$C$17 -> 742.58895 | M34: =IF(K34>0,D34/(K34*$C$17),"") -> 5.5697781
A35: Ritual (venta aparte con publicidad) | B35: =Resumen!C13 -> 48.657997 | C35: =Resumen!F13 -> 75.822497 | D35: =$B$8*B35+(1-$B$8)*C35 -> 55.449122 | E35: =(B35+Supuestos!$B$16+Supuestos!$B$18)/Supuestos!$B$7 -> 80.822497 | F35: =-Desglose!J15 -> 64.971988 | G35: 0 | H35: 0 | I35: 0 | J35: 1 | K35: 1 | L35: =D35-K35*$C$17 -> -9.5508777 | M35: =IF(K35>0,D35/(K35*$C$17),"") -> 0.85306342
A36: Repuesto Nativo (recompra) | B36: =Resumen!C15 -> 111.69897 | C36: =Resumen!F15 -> 154.62372 | D36: =$B$8*B36+(1-$B$8)*C36 -> 122.43016 | E36: =(B36+Supuestos!$B$16+Supuestos!$B$18)/Supuestos!$B$7 -> 159.62372 | F36: =-Costo_Lima!F36 -> -2.5165207 | I36: 0 | J36: 0 | K36: Recompra: sin CAC
A37: Nativo: mezcla de planes en cada pedido nuevo. Cero y bidones usan el margen de Lima en todo el pais. El Ritual y el bidon de 16 L no rinden si se venden con publicidad a este CAC; el Ritual entra como venta cruzada en el mismo envio.
A38: Mezcla de planes Nativo
A39: Nativo 18 meses | B39: 0.1
A40: Nativo 3 años | B40: 0.7
A41: Nativo 6 años | B41: 0.2
A43: Venta cruzada de Ritual (% de pedidos nuevos): mes 1 | B43: 0.08 | C43: SUPUESTO. Ritual sin kit agregado a un pedido de Nativo: sin segundo envio ni segundo CAC.
A44: Venta cruzada de Ritual (% de pedidos nuevos): mes 12 | B44: 0.2
A45: Utilidad por Ritual vendido en el mismo envio (S/) | B45: =0.85*(Desglose!H14+Desglose!H15+Desglose!H16) -> 54.543206 | C45: Margen entregado del Ritual (sin kit) x 85% de entrega.
...

Sheet Plan_Conservador
A1: Plan a 24 meses - escenario Conservador
A2: Todo son formulas a partir de Plan_Supuestos y de las hojas de costos. Mes 1 = noviembre 2026.
A4: Mes # | B4: 1 | C4: 2 | D4: 3 | E4: 4 | F4: 5 | G4: 6 | H4: 7 | I4: 8 | J4: 9 | K4: 10 | L4: 11 | M4: 12 | N4: 13 | O4: 14 | P4: 15 | Q4: 16 | R4: 17 | S4: 18 | T4: 19 | U4: 20 | V4: 21 | W4: 22 | X4: 23 | Y4: 24
A5: Mes | B5: Nov-26 | C5: Dic-26 | D5: Ene-27 | E5: Feb-27 | F5: Mar-27 | G5: Abr-27 | H5: May-27 | I5: Jun-27 | J5: Jul-27 | K5: Ago-27 | L5: Sep-27 | M5: Oct-27 | N5: Nov-27 | O5: Dic-27 | P5: Ene-28 | Q5: Feb-28 | R5: Mar-28 | S5: Abr-28 | T5: May-28 | U5: Jun-28 | V5: Jul-28 | W5: Ago-28 | X5: Sep-28 | Y5: Oct-28
A7: Gasto Meta (S/) | B7: =MIN(Plan_Supuestos!$B$20,Plan_Supuestos!$B$6*(1+Plan_Supuestos!$B$19)^(B$4-1)) -> 9000 | C7: =MIN(Plan_Supuestos!$B$20,Plan_Supuestos!$B$6*(1+Plan_Supuestos!$B$19)^(C$4-1)) -> 9720 | D7: =MIN(Plan_Supuestos!$B$20,Plan_Supuestos!$B$6*(1+Plan_Supuestos!$B$19)^(D$4-1)) -> 10497.6 | E7: =MIN(Plan_Supuestos!$B$20,Plan_Supuestos!$B$6*(1+Plan_Supuestos!$B$19)^(E$4-1)) -> 11337.408 | F7: =MIN(Plan_Supuestos!$B$20,Plan_Supuestos!$B$6*(1+Plan_Supuestos!$B$19)^(F$4-1)) -> 12244.401 | G7: =MIN(Plan_Supuestos!$B$20,Plan_Supuestos!$B$6*(1+Plan_Supuestos!$B$19)^(G$4-1)) -> 13223.953 | H7: =MIN(Plan_Supuestos!$B$20,Plan_Supuestos!$B$6*(1+Plan_Supuestos!$B$19)^(H$4-1)) -> 14281.869 | I7: =MIN(Plan_Supuestos!$B$20,Plan_Supuestos!$B$6*(1+Plan_Supuestos!$B$19)^(I$4-1)) -> 15424.418 | ... Y7: =MIN(Plan_Supuestos!$B$20,Plan_Supuestos!$B$6*(1+Plan_Supuestos!$B$19)^(Y$4-1)) -> 52843.173
A8: Mejora de CAC acumulada | B8: =MIN(Plan_Supuestos!$B$22,Plan_Supuestos!$B$21*(B$4-1)) -> 0 | C8: =MIN(Plan_Supuestos!$B$22,Plan_Supuestos!$B$21*(C$4-1)) -> 0.005 | D8: =MIN(Plan_Supuestos!$B$22,Plan_Supuestos!$B$21*(D$4-1)) -> 0.01 | E8: =MIN(Plan_Supuestos!$B$22,Plan_Supuestos!$B$21*(E$4-1)) -> 0.015 | F8: =MIN(Plan_Supuestos!$B$22,Plan_Supuestos!$B$21*(F$4-1)) -> 0.02 | G8: =MIN(Plan_Supuestos!$B$22,Plan_Supuestos!$B$21*(G$4-1)) -> 0.025 | H8: =MIN(Plan_Supuestos!$B$22,Plan_Supuestos!$B$21*(H$4-1)) -> 0.03 | I8: =MIN(Plan_Supuestos!$B$22,Plan_Supuestos!$B$21*(I$4-1)) -> 0.035 | ... Y8: =MIN(Plan_Supuestos!$B$22,Plan_Supuestos!$B$21*(Y$4-1)) -> 0.115
A9: CAC (S/ por pedido nuevo, segun mezcla) | B9: =Plan_Supuestos!$B$17*(B7/Plan_Supuestos!$B$6)^Plan_Supuestos!$B$18*(1-B8)*SUMPRODUCT(B17:B22,Plan_Supuestos!$K$30:$K$35) -> 77.6 | C9: =Plan_Supuestos!$B$17*(C7/Plan_Supuestos!$B$6)^Plan_Supuestos!$B$18*(1-C8)*SUMPRODUCT(C17:C22,Plan_Supuestos!$K$30:$K$35) -> 79.394414 | D9: =Plan_Supuestos!$B$17*(D7/Plan_Supuestos!$B$6)^Plan_Supuestos!$B$18*(1-D8)*SUMPRODUCT(D17:D22,Plan_Supuestos!$K$30:$K$35) -> 81.2282 | E9: =Plan_Supuestos!$B$17*(E7/Plan_Supuestos!$B$6)^Plan_Supuestos!$B$18*(1-E8)*SUMPRODUCT(E17:E22,Plan_Supuestos!$K$30:$K$35) -> 83.102149 | F9: =Plan_Supuestos!$B$17*(F7/Plan_Supuestos!$B$6)^Plan_Supuestos!$B$18*(1-F8)*SUMPRODUCT(F17:F22,Plan_Supuestos!$K$30:$K$35) -> 85.017065 | G9: =Plan_Supuestos!$B$17*(G7/Plan_Supuestos!$B$6)^Plan_Supuestos!$B$18*(1-G8)*SUMPRODUCT(G17:G22,Plan_Supuestos!$K$30:$K$35) -> 86.973766 | H9: =Plan_Supuestos!$B$17*(H7/Plan_Supuestos!$B$6)^Plan_Supuestos!$B$18*(1-H8)*SUMPRODUCT(H17:H22,Plan_Supuestos!$K$30:$K$35) -> 88.973084 | I9: =Plan_Supuestos!$B$17*(I7/Plan_Supuestos!$B$6)^Plan_Supuestos!$B$18*(1-I8)*SUMPRODUCT(I17:I22,Plan_Supuestos!$K$30:$K$35) -> 91.015864 | ... Y9: =Plan_Supuestos!$B$17*(Y7/Plan_Supuestos!$B$6)^Plan_Supuestos!$B$18*(1-Y8)*SUMPRODUCT(Y17:Y22,Plan_Supuestos!$K$30:$K$35) -> 128.92008
A10: Pedidos pagados | B10: =B7/B9 -> 115.97938 | C10: =C7/C9 -> 122.42675 | D10: =D7/D9 -> 129.23591 | E10: =E7/E9 -> 136.42737 | F10: =F7/F9 -> 144.02286 | G10: =G7/G9 -> 152.0453 | H10: =H7/H9 -> 160.51898 | I10: =I7/I9 -> 169.46956 | ... Y10: =Y7/Y9 -> 409.89094
A11: Pedidos organicos | B11: =B10*Plan_Supuestos!$B$23 -> 11.597938 | C11: =C10*Plan_Supuestos!$B$23 -> 12.242675 | D11: =D10*Plan_Supuestos!$B$23 -> 12.923591 | E11: =E10*Plan_Supuestos!$B$23 -> 13.642737 | F11: =F10*Plan_Supuestos!$B$23 -> 14.402286 | G11: =G10*Plan_Supuestos!$B$23 -> 15.20453 | H11: =H10*Plan_Supuestos!$B$23 -> 16.051898 | I11: =I10*Plan_Supuestos!$B$23 -> 16.946956 | ... Y11: =Y10*Plan_Supuestos!$B$23 -> 40.989094
A12: Pedidos nuevos | B12: =B10+B11 -> 127.57732 | C12: =C10+C11 -> 134.66942 | D12: =D10+D11 -> 142.1595 | E12: =E10+E11 -> 150.07011 | F12: =F10+F11 -> 158.42514 | G12: =G10+G11 -> 167.24983 | H12: =H10+H11 -> 176.57088 | I12: =I10+I11 -> 186.41652 | ... Y12: =Y10+Y11 -> 450.88004
A13: Pedidos nuevos por dia | B13: =B12/30 -> 4.2525773 | C13: =C12/30 -> 4.4889808 | D13: =D12/30 -> 4.7386499 | E13: =E12/30 -> 5.0023371 | F13: =F12/30 -> 5.2808381 | G13: =G12/30 -> 5.5749945 | H13: =H12/30 -> 5.885696 | I13: =I12/30 -> 6.2138838 | ... Y13: =Y12/30 -> 15.029335
A14: Pedidos de recompra | B14: =Plan_Supuestos!$B$24*IF(B$4>12,INDEX($B12:$Y12,B$4-12),Plan_Supuestos!$B$7) -> 4.8 | C14: =Plan_Supuestos!$B$24*IF(C$4>12,INDEX($B12:$Y12,C$4-12),Plan_Supuestos!$B$7) -> 4.8 | D14: =Plan_Supuestos!$B$24*IF(D$4>12,INDEX($B12:$Y12,D$4-12),Plan_Supuestos!$B$7) -> 4.8 | E14: =Plan_Supuestos!$B$24*IF(E$4>12,INDEX($B12:$Y12,E$4-12),Plan_Supuestos!$B$7) -> 4.8 | F14: =Plan_Supuestos!$B$24*IF(F$4>12,INDEX($B12:$Y12,F$4-12),Plan_Supuestos!$B$7) -> 4.8 | G14: =Plan_Supuestos!$B$24*IF(G$4>12,INDEX($B12:$Y12,G$4-12),Plan_Supuestos!$B$7) -> 4.8 | H14: =Plan_Supuestos!$B$24*IF(H$4>12,INDEX($B12:$Y12,H$4-12),Plan_Supuestos!$B$7) -> 4.8 | I14: =Plan_Supuestos!$B$24*IF(I$4>12,INDEX($B12:$Y12,I$4-12),Plan_Supuestos!$B$7) -> 4.8 | ... Y14: =Plan_Supuestos!$B$24*IF(Y$4>12,INDEX($B12:$Y12,Y$4-12),Plan_Supuestos!$B$7) -> 18.533488
A15: Pedidos totales | B15: =B12+B14 -> 132.37732 | C15: =C12+C14 -> 139.46942 | D15: =D12+D14 -> 146.9595 | E15: =E12+E14 -> 154.87011 | F15: =F12+F14 -> 163.22514 | G15: =G12+G14 -> 172.04983 | H15: =H12+H14 -> 181.37088 | I15: =I12+I14 -> 191.21652 | ... Y15: =Y12+Y14 -> 469.41352
A16: Avance de la transicion de mezcla | B16: =MIN(1,(B$4-1)/11) -> 0 | C16: =MIN(1,(C$4-1)/11) -> 0.090909091 | D16: =MIN(1,(D$4-1)/11) -> 0.18181818 | E16: =MIN(1,(E$4-1)/11) -> 0.27272727 | F16: =MIN(1,(F$4-1)/11) -> 0.36363636 | G16: =MIN(1,(G$4-1)/11) -> 0.45454545 | H16: =MIN(1,(H$4-1)/11) -> 0.54545455 | I16: =MIN(1,(I$4-1)/11) -> 0.63636364 | ... Y16: =MIN(1,(Y$4-1)/11) -> 1
A17: Mezcla: Nativo | B17: =1-SUM(B18:B22) -> 0.82 | C17: =1-SUM(C18:C22) -> 0.81363636 | D17: =1-SUM(D18:D22) -> 0.80727273 | E17: =1-SUM(E18:E22) -> 0.80090909 | F17: =1-SUM(F18:F22) -> 0.79454545 | G17: =1-SUM(G18:G22) -> 0.78818182 | H17: =1-SUM(H18:H22) -> 0.78181818 | I17: =1-SUM(I18:I22) -> 0.77545455 | ... Y17: =1-SUM(Y18:Y22) -> 0.75
A18: Mezcla: Vivo | B18: =Plan_Supuestos!$G$31+(Plan_Supuestos!$H$31-Plan_Supuestos!$G$31)*B16 -> 0.08 | C18: =Plan_Supuestos!$G$31+(Plan_Supuestos!$H$31-Plan_Supuestos!$G$31)*C16 -> 0.077272727 | D18: =Plan_Supuestos!$G$31+(Plan_Supuestos!$H$31-Plan_Supuestos!$G$31)*D16 -> 0.074545455 | E18: =Plan_Supuestos!$G$31+(Plan_Supuestos!$H$31-Plan_Supuestos!$G$31)*E16 -> 0.071818182 | F18: =Plan_Supuestos!$G$31+(Plan_Supuestos!$H$31-Plan_Supuestos!$G$31)*F16 -> 0.069090909 | G18: =Plan_Supuestos!$G$31+(Plan_Supuestos!$H$31-Plan_Supuestos!$G$31)*G16 -> 0.066363636 | H18: =Plan_Supuestos!$G$31+(Plan_Supuestos!$H$31-Plan_Supuestos!$G$31)*H16 -> 0.063636364 | I18: =Plan_Supuestos!$G$31+(Plan_Supuestos!$H$31-Plan_Supuestos!$G$31)*I16 -> 0.060909091 | ... Y18: =Plan_Supuestos!$G$31+(Plan_Supuestos!$H$31-Plan_Supuestos!$G$31)*Y16 -> 0.05
A19: Mezcla: Bidon 22 L | B19: =Plan_Supuestos!$G$32+(Plan_Supuestos!$H$32-Plan_Supuestos!$G$32)*B16 -> 0.05 | C19: =Plan_Supuestos!$G$32+(Plan_Supuestos!$H$32-Plan_Supuestos!$G$32)*C16 -> 0.054545455 | D19: =Plan_Supuestos!$G$32+(Plan_Supuestos!$H$32-Plan_Supuestos!$G$32)*D16 -> 0.059090909 | E19: =Plan_Supuestos!$G$32+(Plan_Supuestos!$H$32-Plan_Supuestos!$G$32)*E16 -> 0.063636364 | F19: =Plan_Supuestos!$G$32+(Plan_Supuestos!$H$32-Plan_Supuestos!$G$32)*F16 -> 0.068181818 | G19: =Plan_Supuestos!$G$32+(Plan_Supuestos!$H$32-Plan_Supuestos!$G$32)*G16 -> 0.072727273 | H19: =Plan_Supuestos!$G$32+(Plan_Supuestos!$H$32-Plan_Supuestos!$G$32)*H16 -> 0.077272727 | I19: =Plan_Supuestos!$G$32+(Plan_Supuestos!$H$32-Plan_Supuestos!$G$32)*I16 -> 0.081818182 | ... Y19: =Plan_Supuestos!$G$32+(Plan_Supuestos!$H$32-Plan_Supuestos!$G$32)*Y16 -> 0.1
A20: Mezcla: Bidon 16 L | B20: =Plan_Supuestos!$G$33+(Plan_Supuestos!$H$33-Plan_Supuestos!$G$33)*B16 -> 0.04 | C20: =Plan_Supuestos!$G$33+(Plan_Supuestos!$H$33-Plan_Supuestos!$G$33)*C16 -> 0.041818182 | D20: =Plan_Supuestos!$G$33+(Plan_Supuestos!$H$33-Plan_Supuestos!$G$33)*D16 -> 0.043636364 | E20: =Plan_Supuestos!$G$33+(Plan_Supuestos!$H$33-Plan_Supuestos!$G$33)*E16 -> 0.045454545 | F20: =Plan_Supuestos!$G$33+(Plan_Supuestos!$H$33-Plan_Supuestos!$G$33)*F16 -> 0.047272727 | G20: =Plan_Supuestos!$G$33+(Plan_Supuestos!$H$33-Plan_Supuestos!$G$33)*G16 -> 0.049090909 | H20: =Plan_Supuestos!$G$33+(Plan_Supuestos!$H$33-Plan_Supuestos!$G$33)*H16 -> 0.050909091 | I20: =Plan_Supuestos!$G$33+(Plan_Supuestos!$H$33-Plan_Supuestos!$G$33)*I16 -> 0.052727273 | ... Y20: =Plan_Supuestos!$G$33+(Plan_Supuestos!$H$33-Plan_Supuestos!$G$33)*Y16 -> 0.06
A21: Mezcla: Cero | B21: =Plan_Supuestos!$G$34+(Plan_Supuestos!$B$25-Plan_Supuestos!$G$34)*B16 -> 0.01 | C21: =Plan_Supuestos!$G$34+(Plan_Supuestos!$B$25-Plan_Supuestos!$G$34)*C16 -> 0.012727273 | D21: =Plan_Supuestos!$G$34+(Plan_Supuestos!$B$25-Plan_Supuestos!$G$34)*D16 -> 0.015454545 | E21: =Plan_Supuestos!$G$34+(Plan_Supuestos!$B$25-Plan_Supuestos!$G$34)*E16 -> 0.018181818 | F21: =Plan_Supuestos!$G$34+(Plan_Supuestos!$B$25-Plan_Supuestos!$G$34)*F16 -> 0.020909091 | G21: =Plan_Supuestos!$G$34+(Plan_Supuestos!$B$25-Plan_Supuestos!$G$34)*G16 -> 0.023636364 | H21: =Plan_Supuestos!$G$34+(Plan_Supuestos!$B$25-Plan_Supuestos!$G$34)*H16 -> 0.026363636 | I21: =Plan_Supuestos!$G$34+(Plan_Supuestos!$B$25-Plan_Supuestos!$G$34)*I16 -> 0.029090909 | ... Y21: =Plan_Supuestos!$G$34+(Plan_Supuestos!$B$25-Plan_Supuestos!$G$34)*Y16 -> 0.04
A22: Mezcla: Ritual (venta aparte) | B22: =Plan_Supuestos!$G$35+(Plan_Supuestos!$H$35-Plan_Supuestos!$G$35)*B16 -> 0 | C22: =Plan_Supuestos!$G$35+(Plan_Supuestos!$H$35-Plan_Supuestos!$G$35)*C16 -> 0 | D22: =Plan_Supuestos!$G$35+(Plan_Supuestos!$H$35-Plan_Supuestos!$G$35)*D16 -> 0 | E22: =Plan_Supuestos!$G$35+(Plan_Supuestos!$H$35-Plan_Supuestos!$G$35)*E16 -> 0 | F22: =Plan_Supuestos!$G$35+(Plan_Supuestos!$H$35-Plan_Supuestos!$G$35)*F16 -> 0 | G22: =Plan_Supuestos!$G$35+(Plan_Supuestos!$H$35-Plan_Supuestos!$G$35)*G16 -> 0 | H22: =Plan_Supuestos!$G$35+(Plan_Supuestos!$H$35-Plan_Supuestos!$G$35)*H16 -> 0 | I22: =Plan_Supuestos!$G$35+(Plan_Supuestos!$H$35-Plan_Supuestos!$G$35)*I16 -> 0 | ... Y22: =Plan_Supuestos!$G$35+(Plan_Supuestos!$H$35-Plan_Supuestos!$G$35)*Y16 -> 0
A23: Utilidad por pedido nuevo antes de publicidad (S/) | B23: =SUMPRODUCT(B17:B22,Plan_Supuestos!$D$30:$D$35)+(Plan_Supuestos!$B$43+(Plan_Supuestos!$B$44-Plan_Supuestos!$B$43)*B16)*Plan_Supuestos!$B$45 -> 203.66341 | C23: =SUMPRODUCT(C17:C22,Plan_Supuestos!$D$30:$D$35)+(Plan_Supuestos!$B$43+(Plan_Supuestos!$B$44-Plan_Supuestos!$B$43)*C16)*Plan_Supuestos!$B$45 -> 205.51588 | D23: =SUMPRODUCT(D17:D22,Plan_Supuestos!$D$30:$D$35)+(Plan_Supuestos!$B$43+(Plan_Supuestos!$B$44-Plan_Supuestos!$B$43)*D16)*Plan_Supuestos!$B$45 -> 207.36835 | E23: =SUMPRODUCT(E17:E22,Plan_Supuestos!$D$30:$D$35)+(Plan_Supuestos!$B$43+(Plan_Supuestos!$B$44-Plan_Supuestos!$B$43)*E16)*Plan_Supuestos!$B$45 -> 209.22082 | F23: =SUMPRODUCT(F17:F22,Plan_Supuestos!$D$30:$D$35)+(Plan_Supuestos!$B$43+(Plan_Supuestos!$B$44-Plan_Supuestos!$B$43)*F16)*Plan_Supuestos!$B$45 -> 211.07329 | G23: =SUMPRODUCT(G17:G22,Plan_Supuestos!$D$30:$D$35)+(Plan_Supuestos!$B$43+(Plan_Supuestos!$B$44-Plan_Supuestos!$B$43)*G16)*Plan_Supuestos!$B$45 -> 212.92576 | H23: =SUMPRODUCT(H17:H22,Plan_Supuestos!$D$30:$D$35)+(Plan_Supuestos!$B$43+(Plan_Supuestos!$B$44-Plan_Supuestos!$B$43)*H16)*Plan_Supuestos!$B$45 -> 214.77823 | I23: =SUMPRODUCT(I17:I22,Plan_Supuestos!$D$30:$D$35)+(Plan_Supuestos!$B$43+(Plan_Supuestos!$B$44-Plan_Supuestos!$B$43)*I16)*Plan_Supuestos!$B$45 -> 216.6307 | ... Y23: =SUMPRODUCT(Y17:Y22,Plan_Supuestos!$D$30:$D$35)+(Plan_Supuestos!$B$43+(Plan_Supuestos!$B$44-Plan_Supuestos!$B$43)*Y16)*Plan_Supuestos!$B$45 -> 224.04058
A24: Mejora por entrega en Lima por pedido (S/) | B24: =Plan_Supuestos!$B$26*MIN(1,B$4/6)*Plan_Supuestos!$B$8*SUMPRODUCT(B17:B22,Plan_Supuestos!$E$30:$E$35) -> 0 | C24: =Plan_Supuestos!$B$26*MIN(1,C$4/6)*Plan_Supuestos!$B$8*SUMPRODUCT(C17:C22,Plan_Supuestos!$E$30:$E$35) -> 0 | D24: =Plan_Supuestos!$B$26*MIN(1,D$4/6)*Plan_Supuestos!$B$8*SUMPRODUCT(D17:D22,Plan_Supuestos!$E$30:$E$35) -> 0 | E24: =Plan_Supuestos!$B$26*MIN(1,E$4/6)*Plan_Supuestos!$B$8*SUMPRODUCT(E17:E22,Plan_Supuestos!$E$30:$E$35) -> 0 | F24: =Plan_Supuestos!$B$26*MIN(1,F$4/6)*Plan_Supuestos!$B$8*SUMPRODUCT(F17:F22,Plan_Supuestos!$E$30:$E$35) -> 0 | G24: =Plan_Supuestos!$B$26*MIN(1,G$4/6)*Plan_Supuestos!$B$8*SUMPRODUCT(G17:G22,Plan_Supuestos!$E$30:$E$35) -> 0 | H24: =Plan_Supuestos!$B$26*MIN(1,H$4/6)*Plan_Supuestos!$B$8*SUMPRODUCT(H17:H22,Plan_Supuestos!$E$30:$E$35) -> 0 | I24: =Plan_Supuestos!$B$26*MIN(1,I$4/6)*Plan_Supuestos!$B$8*SUMPRODUCT(I17:I22,Plan_Supuestos!$E$30:$E$35) -> 0 | ... Y24: =Plan_Supuestos!$B$26*MIN(1,Y$4/6)*Plan_Supuestos!$B$8*SUMPRODUCT(Y17:Y22,Plan_Supuestos!$E$30:$E$35) -> 0
A25: Utilidad pedidos nuevos antes de publicidad | B25: =B12*(B23+B24) -> 25982.832 | C25: =C12*(C23+C24) -> 27676.705 | D25: =D12*(D23+D24) -> 29479.38 | E25: =E12*(E23+E24) -> 31397.792 | F25: =F12*(F23+F24) -> 33439.316 | G25: =G12*(G23+G24) -> 35611.798 | H25: =H12*(H23+H24) -> 37923.581 | I25: =I12*(I23+I24) -> 40383.54 | ... Y25: =Y12*(Y23+Y24) -> 101015.42
A26: Utilidad recompra | B26: =B14*Plan_Supuestos!$D$36 -> 587.66477 | C26: =C14*Plan_Supuestos!$D$36 -> 587.66477 | D26: =D14*Plan_Supuestos!$D$36 -> 587.66477 | E26: =E14*Plan_Supuestos!$D$36 -> 587.66477 | F26: =F14*Plan_Supuestos!$D$36 -> 587.66477 | G26: =G14*Plan_Supuestos!$D$36 -> 587.66477 | H26: =H14*Plan_Supuestos!$D$36 -> 587.66477 | I26: =I14*Plan_Supuestos!$D$36 -> 587.66477 | ... Y26: =Y14*Plan_Supuestos!$D$36 -> 2269.0579
A27: Gasto Meta | B27: =-B7 -> -9000 | C27: =-C7 -> -9720 | D27: =-D7 -> -10497.6 | E27: =-E7 -> -11337.408 | F27: =-F7 -> -12244.401 | G27: =-G7 -> -13223.953 | H27: =-H7 -> -14281.869 | I27: =-I7 -> -15424.418 | ... Y27: =-Y7 -> -52843.173
A28: Utilidad despues de publicidad | B28: =B25+B26+B27 -> 17570.497 | C28: =C25+C26+C27 -> 18544.37 | D28: =D25+D26+D27 -> 19569.445 | E28: =E25+E26+E27 -> 20648.049 | F28: =F25+F26+F27 -> 21782.58 | G28: =G25+G26+G27 -> 22975.51 | H28: =H25+H26+H27 -> 24229.377 | I28: =I25+I26+I27 -> 25546.786 | ... Y28: =Y25+Y26+Y27 -> 50441.309
A29: Costos fijos y variables | B29: =-(Plan_Supuestos!$B$9+Plan_Supuestos!$B$10*B15) -> -16059.019 | C29: =-(Plan_Supuestos!$B$9+Plan_Supuestos!$B$10*C15) -> -16115.755 | D29: =-(Plan_Supuestos!$B$9+Plan_Supuestos!$B$10*D15) -> -16175.676 | E29: =-(Plan_Supuestos!$B$9+Plan_Supuestos!$B$10*E15) -> -16238.961 | F29: =-(Plan_Supuestos!$B$9+Plan_Supuestos!$B$10*F15) -> -16305.801 | G29: =-(Plan_Supuestos!$B$9+Plan_Supuestos!$B$10*G15) -> -16376.399 | H29: =-(Plan_Supuestos!$B$9+Plan_Supuestos!$B$10*H15) -> -16450.967 | I29: =-(Plan_Supuestos!$B$9+Plan_Supuestos!$B$10*I15) -> -16529.732 | ... Y29: =-(Plan_Supuestos!$B$9+Plan_Supuestos!$B$10*Y15) -> -18755.308
A30: Utilidad antes de impuestos | B30: =B28+B29 -> 1511.4781 | C30: =C28+C29 -> 2428.6143 | D30: =D28+D29 -> 3393.7688 | E30: =E28+E29 -> 4409.0877 | F30: =F28+F29 -> 5476.7792 | G30: =G28+G29 -> 6599.1114 | H30: =H28+H29 -> 7778.4098 | I30: =I28+I29 -> 9017.0542 | ... Y30: =Y28+Y29 -> 31686.001
A31: Impuesto | B31: =-MAX(0,B30)*Plan_Supuestos!$B$12 -> 0 | C31: =-MAX(0,C30)*Plan_Supuestos!$B$12 -> 0 | D31: =-MAX(0,D30)*Plan_Supuestos!$B$12 -> 0 | E31: =-MAX(0,E30)*Plan_Supuestos!$B$12 -> 0 | F31: =-MAX(0,F30)*Plan_Supuestos!$B$12 -> 0 | G31: =-MAX(0,G30)*Plan_Supuestos!$B$12 -> 0 | H31: =-MAX(0,H30)*Plan_Supuestos!$B$12 -> 0 | I31: =-MAX(0,I30)*Plan_Supuestos!$B$12 -> 0 | ... Y31: =-MAX(0,Y30)*Plan_Supuestos!$B$12 -> 0
A32: UTILIDAD NETA DEL MES | B32: =B30+B31 -> 1511.4781 | C32: =C30+C31 -> 2428.6143 | D32: =D30+D31 -> 3393.7688 | E32: =E30+E31 -> 4409.0877 | F32: =F30+F31 -> 5476.7792 | G32: =G30+G31 -> 6599.1114 | H32: =H30+H31 -> 7778.4098 | I32: =I30+I31 -> 9017.0542 | ... Y32: =Y30+Y31 -> 31686.001
A33: Utilidad acumulada | B33: =B32 -> 1511.4781 | C33: =B33+C32 -> 3940.0925 | D33: =C33+D32 -> 7333.8613 | E33: =D33+E32 -> 11742.949 | F33: =E33+F32 -> 17219.728 | G33: =F33+G32 -> 23818.84 | H33: =G33+H32 -> 31597.249 | I33: =H33+I32 -> 40614.304 | J33: =I33+J32 -> 50931.778 | ... Y33: =X33+Y32 -> 376507.16
A34: Utilidad ultimos 12 meses | M34: =SUM(B32:M32) -> 90341.838 | N34: =SUM(C32:N32) -> 105231.83 | O34: =SUM(D32:O32) -> 120467.37 | P34: =SUM(E32:P32) -> 136032.11 | Q34: =SUM(F32:Q32) -> 151906.21 | R34: =SUM(G32:R32) -> 168065.96 | S34: =SUM(H32:S32) -> 184483.36 | T34: =SUM(I32:T32) -> 201125.69 | ... Y34: =SUM(N32:Y32) -> 286165.33
A35: Run-rate anual (mes x 12) (S/) | B35: =B32*12 -> 18137.737 | C35: =C32*12 -> 29143.372 | D35: =D32*12 -> 40725.226 | E35: =E32*12 -> 52909.053 | F35: =F32*12 -> 65721.35 | G35: =G32*12 -> 79189.336 | H35: =H32*12 -> 93340.918 | I35: =I32*12 -> 108204.65 | ... Y35: =Y32*12 -> 380232.01
A36: Run-rate anual (US$) | B36: =B35/Plan_Supuestos!$B$13 -> 5182.2106 | C36: =C35/Plan_Supuestos!$B$13 -> 8326.6778 | D36: =D35/Plan_Supuestos!$B$13 -> 11635.779 | E36: =E35/Plan_Supuestos!$B$13 -> 15116.872 | F36: =F35/Plan_Supuestos!$B$13 -> 18777.529 | G36: =G35/Plan_Supuestos!$B$13 -> 22625.525 | H36: =H35/Plan_Supuestos!$B$13 -> 26668.834 | I36: =I35/Plan_Supuestos!$B$13 -> 30915.614 | ... Y36: =Y35/Plan_Supuestos!$B$13 -> 108637.72
A37: ¿Run-rate supera la meta? (1 = si) | B37: =IF(B36>=Plan_Supuestos!$B$14,1,0) -> 0 | C37: =IF(C36>=Plan_Supuestos!$B$14,1,0) -> 0 | D37: =IF(D36>=Plan_Supuestos!$B$14,1,0) -> 0 | E37: =IF(E36>=Plan_Supuestos!$B$14,1,0) -> 0 | F37: =IF(F36>=Plan_Supuestos!$B$14,1,0) -> 0 | G37: =IF(G36>=Plan_Supuestos!$B$14,1,0) -> 0 | H37: =IF(H36>=Plan_Supuestos!$B$14,1,0) -> 0 | I37: =IF(I36>=Plan_Supuestos!$B$14,1,0) -> 0 | ... Y37: =IF(Y36>=Plan_Supuestos!$B$14,1,0) -> 0
A38: Costo de producto del mes | B38: =B12*(Plan_Supuestos!$B$8*Supuestos!$B$7+(1-Plan_Supuestos!$B$8)*Supuestos!$B$8)*SUMPRODUCT(B17:B22,Plan_Supuestos!$F$30:$F$35)+B14*Plan_Supuestos!$F$36 -> 3608.1269 | C38: =C12*(Plan_Supuestos!$B$8*Supuestos!$B$7+(1-Plan_Supuestos!$B$8)*Supuestos!$B$8)*SUMPRODUCT(C17:C22,Plan_Supuestos!$F$30:$F$35)+C14*Plan_Supuestos!$F$36 -> 4014.1873 | D38: =D12*(Plan_Supuestos!$B$8*Supuestos!$B$7+(1-Plan_Supuestos!$B$8)*Supuestos!$B$8)*SUMPRODUCT(D17:D22,Plan_Supuestos!$F$30:$F$35)+D14*Plan_Supuestos!$F$36 -> 4454.3232 | E38: =E12*(Plan_Supuestos!$B$8*Supuestos!$B$7+(1-Plan_Supuestos!$B$8)*Supuestos!$B$8)*SUMPRODUCT(E17:E22,Plan_Supuestos!$F$30:$F$35)+E14*Plan_Supuestos!$F$36 -> 4931.0938 | F38: =F12*(Plan_Supuestos!$B$8*Supuestos!$B$7+(1-Plan_Supuestos!$B$8)*Supuestos!$B$8)*SUMPRODUCT(F17:F22,Plan_Supuestos!$F$30:$F$35)+F14*Plan_Supuestos!$F$36 -> 5447.2405 | G38: =G12*(Plan_Supuestos!$B$8*Supuestos!$B$7+(1-Plan_Supuestos!$B$8)*Supuestos!$B$8)*SUMPRODUCT(G17:G22,Plan_Supuestos!$F$30:$F$35)+G14*Plan_Supuestos!$F$36 -> 6005.6993 | H38: =H12*(Plan_Supuestos!$B$8*Supuestos!$B$7+(1-Plan_Supuestos!$B$8)*Supuestos!$B$8)*SUMPRODUCT(H17:H22,Plan_Supuestos!$F$30:$F$35)+H14*Plan_Supuestos!$F$36 -> 6609.6141 | I38: =I12*(Plan_Supuestos!$B$8*Supuestos!$B$7+(1-Plan_Supuestos!$B$8)*Supuestos!$B$8)*SUMPRODUCT(I17:I22,Plan_Supuestos!$F$30:$F$35)+I14*Plan_Supuestos!$F$36 -> 7262.3513 | ... Y38: =Y12*(Plan_Supuestos!$B$8*Supuestos!$B$7+(1-Plan_Supuestos!$B$8)*Supuestos!$B$8)*SUMPRODUCT(Y17:Y22,Plan_Supuestos!$F$30:$F$35)+Y14*Plan_Supuestos!$F$36 -> 20290.676
A39: Inventario requerido | B39: =B38*Plan_Supuestos!$B$11 -> 18040.634 | C39: =C38*Plan_Supuestos!$B$11 -> 20070.937 | D39: =D38*Plan_Supuestos!$B$11 -> 22271.616 | E39: =E38*Plan_Supuestos!$B$11 -> 24655.469 | F39: =F38*Plan_Supuestos!$B$11 -> 27236.203 | G39: =G38*Plan_Supuestos!$B$11 -> 30028.496 | H39: =H38*Plan_Supuestos!$B$11 -> 33048.071 | I39: =I38*Plan_Supuestos!$B$11 -> 36311.757 | ... Y39: =Y38*Plan_Supuestos!$B$11 -> 101453.38
A40: Variacion de inventario | B40: =0 -> 0 | C40: =C39-B39 -> 2030.3021 | D40: =D39-C39 -> 2200.6793 | E40: =E39-D39 -> 2383.853 | F40: =F39-E39 -> 2580.7336 | G40: =G39-F39 -> 2792.2939 | H40: =H39-G39 -> 3019.5741 | I40: =I39-H39 -> 3263.6862 | J40: =J39-I39 -> 3525.8187 | ... Y40: =Y39-X39 -> 5492.7568
A41: Flujo de caja del mes | B41: =B32-B40 -> 1511.4781 | C41: =C32-C40 -> 398.3122 | D41: =D32-D40 -> 1193.0896 | E41: =E32-E40 -> 2025.2347 | F41: =F32-F40 -> 2896.0456 | G41: =G32-G40 -> 3806.8175 | H41: =H32-H40 -> 4758.8357 | I41: =I32-I40 -> 5753.368 | ... Y41: =Y32-Y40 -> 26193.244
A42: Caja acumulada | B42: =B41 -> 1511.4781 | C42: =B42+C41 -> 1909.7903 | D42: =C42+D41 -> 3102.8799 | E42: =D42+E41 -> 5128.1145 | F42: =E42+F41 -> 8024.1601 | G42: =F42+G41 -> 11830.978 | H42: =G42+H41 -> 16589.813 | I42: =H42+I41 -> 22343.181 | J42: =I42+J41 -> 29134.837 | ... Y42: =X42+Y41 -> 293094.42
...

Sheet Plan_Base
A1: Plan a 24 meses - escenario Base
A2: Todo son formulas a partir de Plan_Supuestos y de las hojas de costos. Mes 1 = noviembre 2026.
A4: Mes # | B4: 1 | C4: 2 | D4: 3 | E4: 4 | F4: 5 | G4: 6 | H4: 7 | I4: 8 | J4: 9 | K4: 10 | L4: 11 | M4: 12 | N4: 13 | O4: 14 | P4: 15 | Q4: 16 | R4: 17 | S4: 18 | T4: 19 | U4: 20 | V4: 21 | W4: 22 | X4: 23 | Y4: 24
A5: Mes | B5: Nov-26 | C5: Dic-26 | D5: Ene-27 | E5: Feb-27 | F5: Mar-27 | G5: Abr-27 | H5: May-27 | I5: Jun-27 | J5: Jul-27 | K5: Ago-27 | L5: Sep-27 | M5: Oct-27 | N5: Nov-27 | O5: Dic-27 | P5: Ene-28 | Q5: Feb-28 | R5: Mar-28 | S5: Abr-28 | T5: May-28 | U5: Jun-28 | V5: Jul-28 | W5: Ago-28 | X5: Sep-28 | Y5: Oct-28
A7: Gasto Meta (S/) | B7: =MIN(Plan_Supuestos!$C$20,Plan_Supuestos!$B$6*(1+Plan_Supuestos!$C$19)^(B$4-1)) -> 9000 | C7: =MIN(Plan_Supuestos!$C$20,Plan_Supuestos!$B$6*(1+Plan_Supuestos!$C$19)^(C$4-1)) -> 10080 | D7: =MIN(Plan_Supuestos!$C$20,Plan_Supuestos!$B$6*(1+Plan_Supuestos!$C$19)^(D$4-1)) -> 11289.6 | E7: =MIN(Plan_Supuestos!$C$20,Plan_Supuestos!$B$6*(1+Plan_Supuestos!$C$19)^(E$4-1)) -> 12644.352 | F7: =MIN(Plan_Supuestos!$C$20,Plan_Supuestos!$B$6*(1+Plan_Supuestos!$C$19)^(F$4-1)) -> 14161.674 | G7: =MIN(Plan_Supuestos!$C$20,Plan_Supuestos!$B$6*(1+Plan_Supuestos!$C$19)^(G$4-1)) -> 15861.075 | H7: =MIN(Plan_Supuestos!$C$20,Plan_Supuestos!$B$6*(1+Plan_Supuestos!$C$19)^(H$4-1)) -> 17764.404 | I7: =MIN(Plan_Supuestos!$C$20,Plan_Supuestos!$B$6*(1+Plan_Supuestos!$C$19)^(I$4-1)) -> 19896.133 | ... Y7: =MIN(Plan_Supuestos!$C$20,Plan_Supuestos!$B$6*(1+Plan_Supuestos!$C$19)^(Y$4-1)) -> 121971.13
A8: Mejora de CAC acumulada | B8: =MIN(Plan_Supuestos!$C$22,Plan_Supuestos!$C$21*(B$4-1)) -> 0 | C8: =MIN(Plan_Supuestos!$C$22,Plan_Supuestos!$C$21*(C$4-1)) -> 0.01 | D8: =MIN(Plan_Supuestos!$C$22,Plan_Supuestos!$C$21*(D$4-1)) -> 0.02 | E8: =MIN(Plan_Supuestos!$C$22,Plan_Supuestos!$C$21*(E$4-1)) -> 0.03 | F8: =MIN(Plan_Supuestos!$C$22,Plan_Supuestos!$C$21*(F$4-1)) -> 0.04 | G8: =MIN(Plan_Supuestos!$C$22,Plan_Supuestos!$C$21*(G$4-1)) -> 0.05 | H8: =MIN(Plan_Supuestos!$C$22,Plan_Supuestos!$C$21*(H$4-1)) -> 0.06 | I8: =MIN(Plan_Supuestos!$C$22,Plan_Supuestos!$C$21*(I$4-1)) -> 0.07 | ... Y8: =MIN(Plan_Supuestos!$C$22,Plan_Supuestos!$C$21*(Y$4-1)) -> 0.2
A9: CAC (S/ por pedido nuevo, segun mezcla) | B9: =Plan_Supuestos!$C$17*(B7/Plan_Supuestos!$B$6)^Plan_Supuestos!$C$18*(1-B8)*SUMPRODUCT(B17:B22,Plan_Supuestos!$K$30:$K$35) -> 63.05 | C9: =Plan_Supuestos!$C$17*(C7/Plan_Supuestos!$B$6)^Plan_Supuestos!$C$18*(1-C8)*SUMPRODUCT(C17:C22,Plan_Supuestos!$K$30:$K$35) -> 64.453995 | D9: =Plan_Supuestos!$C$17*(D7/Plan_Supuestos!$B$6)^Plan_Supuestos!$C$18*(1-D8)*SUMPRODUCT(D17:D22,Plan_Supuestos!$K$30:$K$35) -> 65.881613 | E9: =Plan_Supuestos!$C$17*(E7/Plan_Supuestos!$B$6)^Plan_Supuestos!$C$18*(1-E8)*SUMPRODUCT(E17:E22,Plan_Supuestos!$K$30:$K$35) -> 67.332907 | F9: =Plan_Supuestos!$C$17*(F7/Plan_Supuestos!$B$6)^Plan_Supuestos!$C$18*(1-F8)*SUMPRODUCT(F17:F22,Plan_Supuestos!$K$30:$K$35) -> 68.807913 | G9: =Plan_Supuestos!$C$17*(G7/Plan_Supuestos!$B$6)^Plan_Supuestos!$C$18*(1-G8)*SUMPRODUCT(G17:G22,Plan_Supuestos!$K$30:$K$35) -> 70.306641 | H9: =Plan_Supuestos!$C$17*(H7/Plan_Supuestos!$B$6)^Plan_Supuestos!$C$18*(1-H8)*SUMPRODUCT(H17:H22,Plan_Supuestos!$K$30:$K$35) -> 71.829081 | I9: =Plan_Supuestos!$C$17*(I7/Plan_Supuestos!$B$6)^Plan_Supuestos!$C$18*(1-I8)*SUMPRODUCT(I17:I22,Plan_Supuestos!$K$30:$K$35) -> 73.375197 | ... Y9: =Plan_Supuestos!$C$17*(Y7/Plan_Supuestos!$B$6)^Plan_Supuestos!$C$18*(1-Y8)*SUMPRODUCT(Y17:Y22,Plan_Supuestos!$K$30:$K$35) -> 100.76932
A10: Pedidos pagados | B10: =B7/B9 -> 142.74385 | C10: =C7/C9 -> 156.39062 | D10: =D7/D9 -> 171.36192 | E10: =E7/E9 -> 187.78859 | F10: =F7/F9 -> 205.81462 | G10: =G7/G9 -> 225.59853 | H10: =H7/H9 -> 247.31493 | I10: =I7/I9 -> 271.15611 | ... Y10: =Y7/Y9 -> 1210.3994
A11: Pedidos organicos | B11: =B10*Plan_Supuestos!$C$23 -> 21.411578 | C11: =C10*Plan_Supuestos!$C$23 -> 23.458592 | D11: =D10*Plan_Supuestos!$C$23 -> 25.704289 | E11: =E10*Plan_Supuestos!$C$23 -> 28.168289 | F11: =F10*Plan_Supuestos!$C$23 -> 30.872193 | G11: =G10*Plan_Supuestos!$C$23 -> 33.83978 | H11: =H10*Plan_Supuestos!$C$23 -> 37.09724 | I11: =I10*Plan_Supuestos!$C$23 -> 40.673416 | ... Y11: =Y10*Plan_Supuestos!$C$23 -> 181.5599
A12: Pedidos nuevos | B12: =B10+B11 -> 164.15543 | C12: =C10+C11 -> 179.84921 | D12: =D10+D11 -> 197.06621 | E12: =E10+E11 -> 215.95688 | F12: =F10+F11 -> 236.68681 | G12: =G10+G11 -> 259.43831 | H12: =H10+H11 -> 284.41217 | I12: =I10+I11 -> 311.82952 | ... Y12: =Y10+Y11 -> 1391.9593
A13: Pedidos nuevos por dia | B13: =B12/30 -> 5.4718477 | C13: =C12/30 -> 5.9949736 | D13: =D12/30 -> 6.5688738 | E13: =E12/30 -> 7.1985628 | F13: =F12/30 -> 7.8895603 | G13: =G12/30 -> 8.6479438 | H13: =H12/30 -> 9.4804057 | I13: =I12/30 -> 10.394317 | ... Y13: =Y12/30 -> 46.398642
A14: Pedidos de recompra | B14: =Plan_Supuestos!$C$24*IF(B$4>12,INDEX($B12:$Y12,B$4-12),Plan_Supuestos!$B$7) -> 7.2 | C14: =Plan_Supuestos!$C$24*IF(C$4>12,INDEX($B12:$Y12,C$4-12),Plan_Supuestos!$B$7) -> 7.2 | D14: =Plan_Supuestos!$C$24*IF(D$4>12,INDEX($B12:$Y12,D$4-12),Plan_Supuestos!$B$7) -> 7.2 | E14: =Plan_Supuestos!$C$24*IF(E$4>12,INDEX($B12:$Y12,E$4-12),Plan_Supuestos!$B$7) -> 7.2 | F14: =Plan_Supuestos!$C$24*IF(F$4>12,INDEX($B12:$Y12,F$4-12),Plan_Supuestos!$B$7) -> 7.2 | G14: =Plan_Supuestos!$C$24*IF(G$4>12,INDEX($B12:$Y12,G$4-12),Plan_Supuestos!$B$7) -> 7.2 | H14: =Plan_Supuestos!$C$24*IF(H$4>12,INDEX($B12:$Y12,H$4-12),Plan_Supuestos!$B$7) -> 7.2 | I14: =Plan_Supuestos!$C$24*IF(I$4>12,INDEX($B12:$Y12,I$4-12),Plan_Supuestos!$B$7) -> 7.2 | ... Y14: =Plan_Supuestos!$C$24*IF(Y$4>12,INDEX($B12:$Y12,Y$4-12),Plan_Supuestos!$B$7) -> 54.143403
A15: Pedidos totales | B15: =B12+B14 -> 171.35543 | C15: =C12+C14 -> 187.04921 | D15: =D12+D14 -> 204.26621 | E15: =E12+E14 -> 223.15688 | F15: =F12+F14 -> 243.88681 | G15: =G12+G14 -> 266.63831 | H15: =H12+H14 -> 291.61217 | I15: =I12+I14 -> 319.02952 | ... Y15: =Y12+Y14 -> 1446.1027
A16: Avance de la transicion de mezcla | B16: =MIN(1,(B$4-1)/11) -> 0 | C16: =MIN(1,(C$4-1)/11) -> 0.090909091 | D16: =MIN(1,(D$4-1)/11) -> 0.18181818 | E16: =MIN(1,(E$4-1)/11) -> 0.27272727 | F16: =MIN(1,(F$4-1)/11) -> 0.36363636 | G16: =MIN(1,(G$4-1)/11) -> 0.45454545 | H16: =MIN(1,(H$4-1)/11) -> 0.54545455 | I16: =MIN(1,(I$4-1)/11) -> 0.63636364 | ... Y16: =MIN(1,(Y$4-1)/11) -> 1
A17: Mezcla: Nativo | B17: =1-SUM(B18:B22) -> 0.82 | C17: =1-SUM(C18:C22) -> 0.81181818 | D17: =1-SUM(D18:D22) -> 0.80363636 | E17: =1-SUM(E18:E22) -> 0.79545455 | F17: =1-SUM(F18:F22) -> 0.78727273 | G17: =1-SUM(G18:G22) -> 0.77909091 | H17: =1-SUM(H18:H22) -> 0.77090909 | I17: =1-SUM(I18:I22) -> 0.76272727 | ... Y17: =1-SUM(Y18:Y22) -> 0.73
A18: Mezcla: Vivo | B18: =Plan_Supuestos!$G$31+(Plan_Supuestos!$H$31-Plan_Supuestos!$G$31)*B16 -> 0.08 | C18: =Plan_Supuestos!$G$31+(Plan_Supuestos!$H$31-Plan_Supuestos!$G$31)*C16 -> 0.077272727 | D18: =Plan_Supuestos!$G$31+(Plan_Supuestos!$H$31-Plan_Supuestos!$G$31)*D16 -> 0.074545455 | E18: =Plan_Supuestos!$G$31+(Plan_Supuestos!$H$31-Plan_Supuestos!$G$31)*E16 -> 0.071818182 | F18: =Plan_Supuestos!$G$31+(Plan_Supuestos!$H$31-Plan_Supuestos!$G$31)*F16 -> 0.069090909 | G18: =Plan_Supuestos!$G$31+(Plan_Supuestos!$H$31-Plan_Supuestos!$G$31)*G16 -> 0.066363636 | H18: =Plan_Supuestos!$G$31+(Plan_Supuestos!$H$31-Plan_Supuestos!$G$31)*H16 -> 0.063636364 | I18: =Plan_Supuestos!$G$31+(Plan_Supuestos!$H$31-Plan_Supuestos!$G$31)*I16 -> 0.060909091 | ... Y18: =Plan_Supuestos!$G$31+(Plan_Supuestos!$H$31-Plan_Supuestos!$G$31)*Y16 -> 0.05
A19: Mezcla: Bidon 22 L | B19: =Plan_Supuestos!$G$32+(Plan_Supuestos!$H$32-Plan_Supuestos!$G$32)*B16 -> 0.05 | C19: =Plan_Supuestos!$G$32+(Plan_Supuestos!$H$32-Plan_Supuestos!$G$32)*C16 -> 0.054545455 | D19: =Plan_Supuestos!$G$32+(Plan_Supuestos!$H$32-Plan_Supuestos!$G$32)*D16 -> 0.059090909 | E19: =Plan_Supuestos!$G$32+(Plan_Supuestos!$H$32-Plan_Supuestos!$G$32)*E16 -> 0.063636364 | F19: =Plan_Supuestos!$G$32+(Plan_Supuestos!$H$32-Plan_Supuestos!$G$32)*F16 -> 0.068181818 | G19: =Plan_Supuestos!$G$32+(Plan_Supuestos!$H$32-Plan_Supuestos!$G$32)*G16 -> 0.072727273 | H19: =Plan_Supuestos!$G$32+(Plan_Supuestos!$H$32-Plan_Supuestos!$G$32)*H16 -> 0.077272727 | I19: =Plan_Supuestos!$G$32+(Plan_Supuestos!$H$32-Plan_Supuestos!$G$32)*I16 -> 0.081818182 | ... Y19: =Plan_Supuestos!$G$32+(Plan_Supuestos!$H$32-Plan_Supuestos!$G$32)*Y16 -> 0.1
A20: Mezcla: Bidon 16 L | B20: =Plan_Supuestos!$G$33+(Plan_Supuestos!$H$33-Plan_Supuestos!$G$33)*B16 -> 0.04 | C20: =Plan_Supuestos!$G$33+(Plan_Supuestos!$H$33-Plan_Supuestos!$G$33)*C16 -> 0.041818182 | D20: =Plan_Supuestos!$G$33+(Plan_Supuestos!$H$33-Plan_Supuestos!$G$33)*D16 -> 0.043636364 | E20: =Plan_Supuestos!$G$33+(Plan_Supuestos!$H$33-Plan_Supuestos!$G$33)*E16 -> 0.045454545 | F20: =Plan_Supuestos!$G$33+(Plan_Supuestos!$H$33-Plan_Supuestos!$G$33)*F16 -> 0.047272727 | G20: =Plan_Supuestos!$G$33+(Plan_Supuestos!$H$33-Plan_Supuestos!$G$33)*G16 -> 0.049090909 | H20: =Plan_Supuestos!$G$33+(Plan_Supuestos!$H$33-Plan_Supuestos!$G$33)*H16 -> 0.050909091 | I20: =Plan_Supuestos!$G$33+(Plan_Supuestos!$H$33-Plan_Supuestos!$G$33)*I16 -> 0.052727273 | ... Y20: =Plan_Supuestos!$G$33+(Plan_Supuestos!$H$33-Plan_Supuestos!$G$33)*Y16 -> 0.06
A21: Mezcla: Cero | B21: =Plan_Supuestos!$G$34+(Plan_Supuestos!$C$25-Plan_Supuestos!$G$34)*B16 -> 0.01 | C21: =Plan_Supuestos!$G$34+(Plan_Supuestos!$C$25-Plan_Supuestos!$G$34)*C16 -> 0.014545455 | D21: =Plan_Supuestos!$G$34+(Plan_Supuestos!$C$25-Plan_Supuestos!$G$34)*D16 -> 0.019090909 | E21: =Plan_Supuestos!$G$34+(Plan_Supuestos!$C$25-Plan_Supuestos!$G$34)*E16 -> 0.023636364 | F21: =Plan_Supuestos!$G$34+(Plan_Supuestos!$C$25-Plan_Supuestos!$G$34)*F16 -> 0.028181818 | G21: =Plan_Supuestos!$G$34+(Plan_Supuestos!$C$25-Plan_Supuestos!$G$34)*G16 -> 0.032727273 | H21: =Plan_Supuestos!$G$34+(Plan_Supuestos!$C$25-Plan_Supuestos!$G$34)*H16 -> 0.037272727 | I21: =Plan_Supuestos!$G$34+(Plan_Supuestos!$C$25-Plan_Supuestos!$G$34)*I16 -> 0.041818182 | ... Y21: =Plan_Supuestos!$G$34+(Plan_Supuestos!$C$25-Plan_Supuestos!$G$34)*Y16 -> 0.06
A22: Mezcla: Ritual (venta aparte) | B22: =Plan_Supuestos!$G$35+(Plan_Supuestos!$H$35-Plan_Supuestos!$G$35)*B16 -> 0 | C22: =Plan_Supuestos!$G$35+(Plan_Supuestos!$H$35-Plan_Supuestos!$G$35)*C16 -> 0 | D22: =Plan_Supuestos!$G$35+(Plan_Supuestos!$H$35-Plan_Supuestos!$G$35)*D16 -> 0 | E22: =Plan_Supuestos!$G$35+(Plan_Supuestos!$H$35-Plan_Supuestos!$G$35)*E16 -> 0 | F22: =Plan_Supuestos!$G$35+(Plan_Supuestos!$H$35-Plan_Supuestos!$G$35)*F16 -> 0 | G22: =Plan_Supuestos!$G$35+(Plan_Supuestos!$H$35-Plan_Supuestos!$G$35)*G16 -> 0 | H22: =Plan_Supuestos!$G$35+(Plan_Supuestos!$H$35-Plan_Supuestos!$G$35)*H16 -> 0 | I22: =Plan_Supuestos!$G$35+(Plan_Supuestos!$H$35-Plan_Supuestos!$G$35)*I16 -> 0 | ... Y22: =Plan_Supuestos!$G$35+(Plan_Supuestos!$H$35-Plan_Supuestos!$G$35)*Y16 -> 0
A23: Utilidad por pedido nuevo antes de publicidad (S/) | B23: =SUMPRODUCT(B17:B22,Plan_Supuestos!$D$30:$D$35)+(Plan_Supuestos!$B$43+(Plan_Supuestos!$B$44-Plan_Supuestos!$B$43)*B16)*Plan_Supuestos!$B$45 -> 203.66341 | C23: =SUMPRODUCT(C17:C22,Plan_Supuestos!$D$30:$D$35)+(Plan_Supuestos!$B$43+(Plan_Supuestos!$B$44-Plan_Supuestos!$B$43)*C16)*Plan_Supuestos!$B$45 -> 206.77893 | D23: =SUMPRODUCT(D17:D22,Plan_Supuestos!$D$30:$D$35)+(Plan_Supuestos!$B$43+(Plan_Supuestos!$B$44-Plan_Supuestos!$B$43)*D16)*Plan_Supuestos!$B$45 -> 209.89446 | E23: =SUMPRODUCT(E17:E22,Plan_Supuestos!$D$30:$D$35)+(Plan_Supuestos!$B$43+(Plan_Supuestos!$B$44-Plan_Supuestos!$B$43)*E16)*Plan_Supuestos!$B$45 -> 213.00998 | F23: =SUMPRODUCT(F17:F22,Plan_Supuestos!$D$30:$D$35)+(Plan_Supuestos!$B$43+(Plan_Supuestos!$B$44-Plan_Supuestos!$B$43)*F16)*Plan_Supuestos!$B$45 -> 216.12551 | G23: =SUMPRODUCT(G17:G22,Plan_Supuestos!$D$30:$D$35)+(Plan_Supuestos!$B$43+(Plan_Supuestos!$B$44-Plan_Supuestos!$B$43)*G16)*Plan_Supuestos!$B$45 -> 219.24103 | H23: =SUMPRODUCT(H17:H22,Plan_Supuestos!$D$30:$D$35)+(Plan_Supuestos!$B$43+(Plan_Supuestos!$B$44-Plan_Supuestos!$B$43)*H16)*Plan_Supuestos!$B$45 -> 222.35655 | I23: =SUMPRODUCT(I17:I22,Plan_Supuestos!$D$30:$D$35)+(Plan_Supuestos!$B$43+(Plan_Supuestos!$B$44-Plan_Supuestos!$B$43)*I16)*Plan_Supuestos!$B$45 -> 225.47208 | ... Y23: =SUMPRODUCT(Y17:Y22,Plan_Supuestos!$D$30:$D$35)+(Plan_Supuestos!$B$43+(Plan_Supuestos!$B$44-Plan_Supuestos!$B$43)*Y16)*Plan_Supuestos!$B$45 -> 237.93417
A24: Mejora por entrega en Lima por pedido (S/) | B24: =Plan_Supuestos!$C$26*MIN(1,B$4/6)*Plan_Supuestos!$B$8*SUMPRODUCT(B17:B22,Plan_Supuestos!$E$30:$E$35) -> 1.572847 | C24: =Plan_Supuestos!$C$26*MIN(1,C$4/6)*Plan_Supuestos!$B$8*SUMPRODUCT(C17:C22,Plan_Supuestos!$E$30:$E$35) -> 3.187607 | D24: =Plan_Supuestos!$C$26*MIN(1,D$4/6)*Plan_Supuestos!$B$8*SUMPRODUCT(D17:D22,Plan_Supuestos!$E$30:$E$35) -> 4.84428 | E24: =Plan_Supuestos!$C$26*MIN(1,E$4/6)*Plan_Supuestos!$B$8*SUMPRODUCT(E17:E22,Plan_Supuestos!$E$30:$E$35) -> 6.542866 | F24: =Plan_Supuestos!$C$26*MIN(1,F$4/6)*Plan_Supuestos!$B$8*SUMPRODUCT(F17:F22,Plan_Supuestos!$E$30:$E$35) -> 8.2833651 | G24: =Plan_Supuestos!$C$26*MIN(1,G$4/6)*Plan_Supuestos!$B$8*SUMPRODUCT(G17:G22,Plan_Supuestos!$E$30:$E$35) -> 10.065777 | H24: =Plan_Supuestos!$C$26*MIN(1,H$4/6)*Plan_Supuestos!$B$8*SUMPRODUCT(H17:H22,Plan_Supuestos!$E$30:$E$35) -> 10.191516 | I24: =Plan_Supuestos!$C$26*MIN(1,I$4/6)*Plan_Supuestos!$B$8*SUMPRODUCT(I17:I22,Plan_Supuestos!$E$30:$E$35) -> 10.317255 | ... Y24: =Plan_Supuestos!$C$26*MIN(1,Y$4/6)*Plan_Supuestos!$B$8*SUMPRODUCT(Y17:Y22,Plan_Supuestos!$E$30:$E$35) -> 10.820211
A25: Utilidad pedidos nuevos antes de publicidad | B25: =B12*(B23+B24) -> 33690.646 | C25: =C12*(C23+C24) -> 37762.316 | D25: =D12*(D23+D24) -> 42317.75 | E25: =E12*(E23+E24) -> 47413.949 | F25: =F12*(F23+F24) -> 53114.62 | G25: =G12*(G23+G24) -> 59490.971 | H25: =H12*(H23+H24) -> 66139.501 | I25: =I12*(I23+I24) -> 73526.075 | ... Y25: =Y12*(Y23+Y24) -> 346255.97
A26: Utilidad recompra | B26: =B14*Plan_Supuestos!$D$36 -> 881.49715 | C26: =C14*Plan_Supuestos!$D$36 -> 881.49715 | D26: =D14*Plan_Supuestos!$D$36 -> 881.49715 | E26: =E14*Plan_Supuestos!$D$36 -> 881.49715 | F26: =F14*Plan_Supuestos!$D$36 -> 881.49715 | G26: =G14*Plan_Supuestos!$D$36 -> 881.49715 | H26: =H14*Plan_Supuestos!$D$36 -> 881.49715 | I26: =I14*Plan_Supuestos!$D$36 -> 881.49715 | ... Y26: =Y14*Plan_Supuestos!$D$36 -> 6628.7854
A27: Gasto Meta | B27: =-B7 -> -9000 | C27: =-C7 -> -10080 | D27: =-D7 -> -11289.6 | E27: =-E7 -> -12644.352 | F27: =-F7 -> -14161.674 | G27: =-G7 -> -15861.075 | H27: =-H7 -> -17764.404 | I27: =-I7 -> -19896.133 | ... Y27: =-Y7 -> -121971.13
A28: Utilidad despues de publicidad | B28: =B25+B26+B27 -> 25572.144 | C28: =C25+C26+C27 -> 28563.813 | D28: =D25+D26+D27 -> 31909.647 | E28: =E25+E26+E27 -> 35651.094 | F28: =F25+F26+F27 -> 39834.443 | G28: =G25+G26+G27 -> 44511.393 | H28: =H25+H26+H27 -> 49256.594 | I28: =I25+I26+I27 -> 54511.44 | ... Y28: =Y25+Y26+Y27 -> 230913.63
A29: Costos fijos y variables | B29: =-(Plan_Supuestos!$B$9+Plan_Supuestos!$B$10*B15) -> -16370.843 | C29: =-(Plan_Supuestos!$B$9+Plan_Supuestos!$B$10*C15) -> -16496.394 | D29: =-(Plan_Supuestos!$B$9+Plan_Supuestos!$B$10*D15) -> -16634.13 | E29: =-(Plan_Supuestos!$B$9+Plan_Supuestos!$B$10*E15) -> -16785.255 | F29: =-(Plan_Supuestos!$B$9+Plan_Supuestos!$B$10*F15) -> -16951.094 | G29: =-(Plan_Supuestos!$B$9+Plan_Supuestos!$B$10*G15) -> -17133.107 | H29: =-(Plan_Supuestos!$B$9+Plan_Supuestos!$B$10*H15) -> -17332.897 | I29: =-(Plan_Supuestos!$B$9+Plan_Supuestos!$B$10*I15) -> -17552.236 | ... Y29: =-(Plan_Supuestos!$B$9+Plan_Supuestos!$B$10*Y15) -> -26568.821
A30: Utilidad antes de impuestos | B30: =B28+B29 -> 9201.3001 | C30: =C28+C29 -> 12067.42 | D30: =D28+D29 -> 15275.517 | E30: =E28+E29 -> 18865.839 | F30: =F28+F29 -> 22883.348 | G30: =G28+G29 -> 27378.287 | H30: =H28+H29 -> 31923.697 | I30: =I28+I29 -> 36959.203 | ... Y30: =Y28+Y29 -> 204344.81
A31: Impuesto | B31: =-MAX(0,B30)*Plan_Supuestos!$B$12 -> 0 | C31: =-MAX(0,C30)*Plan_Supuestos!$B$12 -> 0 | D31: =-MAX(0,D30)*Plan_Supuestos!$B$12 -> 0 | E31: =-MAX(0,E30)*Plan_Supuestos!$B$12 -> 0 | F31: =-MAX(0,F30)*Plan_Supuestos!$B$12 -> 0 | G31: =-MAX(0,G30)*Plan_Supuestos!$B$12 -> 0 | H31: =-MAX(0,H30)*Plan_Supuestos!$B$12 -> 0 | I31: =-MAX(0,I30)*Plan_Supuestos!$B$12 -> 0 | ... Y31: =-MAX(0,Y30)*Plan_Supuestos!$B$12 -> 0
A32: UTILIDAD NETA DEL MES | B32: =B30+B31 -> 9201.3001 | C32: =C30+C31 -> 12067.42 | D32: =D30+D31 -> 15275.517 | E32: =E30+E31 -> 18865.839 | F32: =F30+F31 -> 22883.348 | G32: =G30+G31 -> 27378.287 | H32: =H30+H31 -> 31923.697 | I32: =I30+I31 -> 36959.203 | ... Y32: =Y30+Y31 -> 204344.81
A33: Utilidad acumulada | B33: =B32 -> 9201.3001 | C33: =B33+C32 -> 21268.72 | D33: =C33+D32 -> 36544.237 | E33: =D33+E32 -> 55410.076 | F33: =E33+F32 -> 78293.424 | G33: =F33+G32 -> 105671.71 | H33: =G33+H32 -> 137595.41 | I33: =H33+I32 -> 174554.61 | J33: =I33+J32 -> 217092.06 | ... Y33: =X33+Y32 -> 1966292.1
A34: Utilidad ultimos 12 meses | M34: =SUM(B32:M32) -> 384514.7 | N34: =SUM(C32:N32) -> 447111.49 | O34: =SUM(D32:O32) -> 514957.58 | P34: =SUM(E32:P32) -> 588471.75 | Q34: =SUM(F32:Q32) -> 668104.43 | R34: =SUM(G32:R32) -> 754339.84 | S34: =SUM(H32:S32) -> 847698.33 | T34: =SUM(I32:T32) -> 949221.94 | ... Y34: =SUM(N32:Y32) -> 1581777.4
A35: Run-rate anual (mes x 12) (S/) | B35: =B32*12 -> 110415.6 | C35: =C32*12 -> 144809.03 | D35: =D32*12 -> 183306.21 | E35: =E32*12 -> 226390.06 | F35: =F32*12 -> 274600.18 | G35: =G32*12 -> 328539.44 | H35: =H32*12 -> 383084.36 | I35: =I32*12 -> 443510.44 | ... Y35: =Y32*12 -> 2452137.7
A36: Run-rate anual (US$) | B36: =B35/Plan_Supuestos!$B$13 -> 31547.315 | C36: =C35/Plan_Supuestos!$B$13 -> 41374.01 | D36: =D35/Plan_Supuestos!$B$13 -> 52373.202 | E36: =E35/Plan_Supuestos!$B$13 -> 64682.876 | F36: =F35/Plan_Supuestos!$B$13 -> 78457.194 | G36: =G35/Plan_Supuestos!$B$13 -> 93868.412 | H36: =H35/Plan_Supuestos!$B$13 -> 109452.67 | I36: =I35/Plan_Supuestos!$B$13 -> 126717.27 | ... Y36: =Y35/Plan_Supuestos!$B$13 -> 700610.77
A37: ¿Run-rate supera la meta? (1 = si) | B37: =IF(B36>=Plan_Supuestos!$B$14,1,0) -> 0 | C37: =IF(C36>=Plan_Supuestos!$B$14,1,0) -> 0 | D37: =IF(D36>=Plan_Supuestos!$B$14,1,0) -> 0 | E37: =IF(E36>=Plan_Supuestos!$B$14,1,0) -> 0 | F37: =IF(F36>=Plan_Supuestos!$B$14,1,0) -> 0 | G37: =IF(G36>=Plan_Supuestos!$B$14,1,0) -> 0 | H37: =IF(H36>=Plan_Supuestos!$B$14,1,0) -> 0 | I37: =IF(I36>=Plan_Supuestos!$B$14,1,0) -> 0 | ... Y37: =IF(Y36>=Plan_Supuestos!$B$14,1,0) -> 0
A38: Costo de producto del mes | B38: =B12*(Plan_Supuestos!$B$8*Supuestos!$B$7+(1-Plan_Supuestos!$B$8)*Supuestos!$B$8)*SUMPRODUCT(B17:B22,Plan_Supuestos!$F$30:$F$35)+B14*Plan_Supuestos!$F$36 -> 4640.0485 | C38: =C12*(Plan_Supuestos!$B$8*Supuestos!$B$7+(1-Plan_Supuestos!$B$8)*Supuestos!$B$8)*SUMPRODUCT(C17:C22,Plan_Supuestos!$F$30:$F$35)+C14*Plan_Supuestos!$F$36 -> 5528.2969 | D38: =D12*(Plan_Supuestos!$B$8*Supuestos!$B$7+(1-Plan_Supuestos!$B$8)*Supuestos!$B$8)*SUMPRODUCT(D17:D22,Plan_Supuestos!$F$30:$F$35)+D14*Plan_Supuestos!$F$36 -> 6544.5697 | E38: =E12*(Plan_Supuestos!$B$8*Supuestos!$B$7+(1-Plan_Supuestos!$B$8)*Supuestos!$B$8)*SUMPRODUCT(E17:E22,Plan_Supuestos!$F$30:$F$35)+E14*Plan_Supuestos!$F$36 -> 7705.5008 | F38: =F12*(Plan_Supuestos!$B$8*Supuestos!$B$7+(1-Plan_Supuestos!$B$8)*Supuestos!$B$8)*SUMPRODUCT(F17:F22,Plan_Supuestos!$F$30:$F$35)+F14*Plan_Supuestos!$F$36 -> 9029.7855 | G38: =G12*(Plan_Supuestos!$B$8*Supuestos!$B$7+(1-Plan_Supuestos!$B$8)*Supuestos!$B$8)*SUMPRODUCT(G17:G22,Plan_Supuestos!$F$30:$F$35)+G14*Plan_Supuestos!$F$36 -> 10538.431 | H38: =H12*(Plan_Supuestos!$B$8*Supuestos!$B$7+(1-Plan_Supuestos!$B$8)*Supuestos!$B$8)*SUMPRODUCT(H17:H22,Plan_Supuestos!$F$30:$F$35)+H14*Plan_Supuestos!$F$36 -> 12255.037 | I38: =I12*(Plan_Supuestos!$B$8*Supuestos!$B$7+(1-Plan_Supuestos!$B$8)*Supuestos!$B$8)*SUMPRODUCT(I17:I22,Plan_Supuestos!$F$30:$F$35)+I14*Plan_Supuestos!$F$36 -> 14206.11 | ... Y38: =Y12*(Plan_Supuestos!$B$8*Supuestos!$B$7+(1-Plan_Supuestos!$B$8)*Supuestos!$B$8)*SUMPRODUCT(Y17:Y22,Plan_Supuestos!$F$30:$F$35)+Y14*Plan_Supuestos!$F$36 -> 77070.387
A39: Inventario requerido | B39: =B38*Plan_Supuestos!$B$11 -> 23200.242 | C39: =C38*Plan_Supuestos!$B$11 -> 27641.485 | D39: =D38*Plan_Supuestos!$B$11 -> 32722.848 | E39: =E38*Plan_Supuestos!$B$11 -> 38527.504 | F39: =F38*Plan_Supuestos!$B$11 -> 45148.928 | G39: =G38*Plan_Supuestos!$B$11 -> 52692.155 | H39: =H38*Plan_Supuestos!$B$11 -> 61275.185 | I39: =I38*Plan_Supuestos!$B$11 -> 71030.548 | ... Y39: =Y38*Plan_Supuestos!$B$11 -> 385351.93
A40: Variacion de inventario | B40: =0 -> 0 | C40: =C39-B39 -> 4441.2422 | D40: =D39-C39 -> 5081.3639 | E40: =E39-D39 -> 5804.6554 | F40: =F39-E39 -> 6621.4237 | G40: =G39-F39 -> 7543.2278 | H40: =H39-G39 -> 8583.0294 | I40: =I39-H39 -> 9755.3636 | J40: =J39-I39 -> 11076.529 | ... Y40: =Y39-X39 -> 31395.498
A41: Flujo de caja del mes | B41: =B32-B40 -> 9201.3001 | C41: =C32-C40 -> 7626.1773 | D41: =D32-D40 -> 10194.153 | E41: =E32-E40 -> 13061.183 | F41: =F32-F40 -> 16261.924 | G41: =G32-G40 -> 19835.059 | H41: =H32-H40 -> 23340.667 | I41: =I32-I40 -> 27203.84 | ... Y41: =Y32-Y40 -> 172949.31
A42: Caja acumulada | B42: =B41 -> 9201.3001 | C42: =B42+C41 -> 16827.477 | D42: =C42+D41 -> 27021.631 | E42: =D42+E41 -> 40082.814 | F42: =E42+F41 -> 56344.739 | G42: =F42+G41 -> 76179.798 | H42: =G42+H41 -> 99520.465 | I42: =H42+I41 -> 126724.3 | J42: =I42+J41 -> 158185.22 | ... Y42: =X42+Y41 -> 1604140.4
...

Sheet Plan_Ambicioso
A1: Plan a 24 meses - escenario Ambicioso
A2: Todo son formulas a partir de Plan_Supuestos y de las hojas de costos. Mes 1 = noviembre 2026.
A4: Mes # | B4: 1 | C4: 2 | D4: 3 | E4: 4 | F4: 5 | G4: 6 | H4: 7 | I4: 8 | J4: 9 | K4: 10 | L4: 11 | M4: 12 | N4: 13 | O4: 14 | P4: 15 | Q4: 16 | R4: 17 | S4: 18 | T4: 19 | U4: 20 | V4: 21 | W4: 22 | X4: 23 | Y4: 24
A5: Mes | B5: Nov-26 | C5: Dic-26 | D5: Ene-27 | E5: Feb-27 | F5: Mar-27 | G5: Abr-27 | H5: May-27 | I5: Jun-27 | J5: Jul-27 | K5: Ago-27 | L5: Sep-27 | M5: Oct-27 | N5: Nov-27 | O5: Dic-27 | P5: Ene-28 | Q5: Feb-28 | R5: Mar-28 | S5: Abr-28 | T5: May-28 | U5: Jun-28 | V5: Jul-28 | W5: Ago-28 | X5: Sep-28 | Y5: Oct-28
A7: Gasto Meta (S/) | B7: =MIN(Plan_Supuestos!$D$20,Plan_Supuestos!$B$6*(1+Plan_Supuestos!$D$19)^(B$4-1)) -> 9000 | C7: =MIN(Plan_Supuestos!$D$20,Plan_Supuestos!$B$6*(1+Plan_Supuestos!$D$19)^(C$4-1)) -> 10350 | D7: =MIN(Plan_Supuestos!$D$20,Plan_Supuestos!$B$6*(1+Plan_Supuestos!$D$19)^(D$4-1)) -> 11902.5 | E7: =MIN(Plan_Supuestos!$D$20,Plan_Supuestos!$B$6*(1+Plan_Supuestos!$D$19)^(E$4-1)) -> 13687.875 | F7: =MIN(Plan_Supuestos!$D$20,Plan_Supuestos!$B$6*(1+Plan_Supuestos!$D$19)^(F$4-1)) -> 15741.056 | G7: =MIN(Plan_Supuestos!$D$20,Plan_Supuestos!$B$6*(1+Plan_Supuestos!$D$19)^(G$4-1)) -> 18102.215 | H7: =MIN(Plan_Supuestos!$D$20,Plan_Supuestos!$B$6*(1+Plan_Supuestos!$D$19)^(H$4-1)) -> 20817.547 | I7: =MIN(Plan_Supuestos!$D$20,Plan_Supuestos!$B$6*(1+Plan_Supuestos!$D$19)^(I$4-1)) -> 23940.179 | ... Y7: =MIN(Plan_Supuestos!$D$20,Plan_Supuestos!$B$6*(1+Plan_Supuestos!$D$19)^(Y$4-1)) -> 224023.12
A8: Mejora de CAC acumulada | B8: =MIN(Plan_Supuestos!$D$22,Plan_Supuestos!$D$21*(B$4-1)) -> 0 | C8: =MIN(Plan_Supuestos!$D$22,Plan_Supuestos!$D$21*(C$4-1)) -> 0.015 | D8: =MIN(Plan_Supuestos!$D$22,Plan_Supuestos!$D$21*(D$4-1)) -> 0.03 | E8: =MIN(Plan_Supuestos!$D$22,Plan_Supuestos!$D$21*(E$4-1)) -> 0.045 | F8: =MIN(Plan_Supuestos!$D$22,Plan_Supuestos!$D$21*(F$4-1)) -> 0.06 | G8: =MIN(Plan_Supuestos!$D$22,Plan_Supuestos!$D$21*(G$4-1)) -> 0.075 | H8: =MIN(Plan_Supuestos!$D$22,Plan_Supuestos!$D$21*(H$4-1)) -> 0.09 | I8: =MIN(Plan_Supuestos!$D$22,Plan_Supuestos!$D$21*(I$4-1)) -> 0.105 | ... Y8: =MIN(Plan_Supuestos!$D$22,Plan_Supuestos!$D$21*(Y$4-1)) -> 0.25
A9: CAC (S/ por pedido nuevo, segun mezcla) | B9: =Plan_Supuestos!$D$17*(B7/Plan_Supuestos!$B$6)^Plan_Supuestos!$D$18*(1-B8)*SUMPRODUCT(B17:B22,Plan_Supuestos!$K$30:$K$35) -> 53.35 | C9: =Plan_Supuestos!$D$17*(C7/Plan_Supuestos!$B$6)^Plan_Supuestos!$D$18*(1-C8)*SUMPRODUCT(C17:C22,Plan_Supuestos!$K$30:$K$35) -> 54.015101 | D9: =Plan_Supuestos!$D$17*(D7/Plan_Supuestos!$B$6)^Plan_Supuestos!$D$18*(1-D8)*SUMPRODUCT(D17:D22,Plan_Supuestos!$K$30:$K$35) -> 54.673488 | E9: =Plan_Supuestos!$D$17*(E7/Plan_Supuestos!$B$6)^Plan_Supuestos!$D$18*(1-E8)*SUMPRODUCT(E17:E22,Plan_Supuestos!$K$30:$K$35) -> 55.324347 | F9: =Plan_Supuestos!$D$17*(F7/Plan_Supuestos!$B$6)^Plan_Supuestos!$D$18*(1-F8)*SUMPRODUCT(F17:F22,Plan_Supuestos!$K$30:$K$35) -> 55.966826 | G9: =Plan_Supuestos!$D$17*(G7/Plan_Supuestos!$B$6)^Plan_Supuestos!$D$18*(1-G8)*SUMPRODUCT(G17:G22,Plan_Supuestos!$K$30:$K$35) -> 56.600037 | H9: =Plan_Supuestos!$D$17*(H7/Plan_Supuestos!$B$6)^Plan_Supuestos!$D$18*(1-H8)*SUMPRODUCT(H17:H22,Plan_Supuestos!$K$30:$K$35) -> 57.22305 | I9: =Plan_Supuestos!$D$17*(I7/Plan_Supuestos!$B$6)^Plan_Supuestos!$D$18*(1-I8)*SUMPRODUCT(I17:I22,Plan_Supuestos!$K$30:$K$35) -> 57.834897 | ... Y9: =Plan_Supuestos!$D$17*(Y7/Plan_Supuestos!$B$6)^Plan_Supuestos!$D$18*(1-Y8)*SUMPRODUCT(Y17:Y22,Plan_Supuestos!$K$30:$K$35) -> 69.480805
A10: Pedidos pagados | B10: =B7/B9 -> 168.69728 | C10: =C7/C9 -> 191.61308 | D10: =D7/D9 -> 217.70149 | E10: =E7/E9 -> 247.41141 | F10: =F7/F9 -> 281.2569 | G10: =G7/G9 -> 319.82691 | H10: =H7/H9 -> 363.79653 | I10: =I7/I9 -> 413.94003 | ... Y10: =Y7/Y9 -> 3224.2447
A11: Pedidos organicos | B11: =B10*Plan_Supuestos!$D$23 -> 33.739456 | C11: =C10*Plan_Supuestos!$D$23 -> 38.322617 | D11: =D10*Plan_Supuestos!$D$23 -> 43.540298 | E11: =E10*Plan_Supuestos!$D$23 -> 49.482283 | F11: =F10*Plan_Supuestos!$D$23 -> 56.25138 | G11: =G10*Plan_Supuestos!$D$23 -> 63.965382 | H11: =H10*Plan_Supuestos!$D$23 -> 72.759306 | I11: =I10*Plan_Supuestos!$D$23 -> 82.788006 | ... Y11: =Y10*Plan_Supuestos!$D$23 -> 644.84894
A12: Pedidos nuevos | B12: =B10+B11 -> 202.43674 | C12: =C10+C11 -> 229.9357 | D12: =D10+D11 -> 261.24179 | E12: =E10+E11 -> 296.8937 | F12: =F10+F11 -> 337.50828 | G12: =G10+G11 -> 383.79229 | H12: =H10+H11 -> 436.55584 | I12: =I10+I11 -> 496.72803 | ... Y12: =Y10+Y11 -> 3869.0937
A13: Pedidos nuevos por dia | B13: =B12/30 -> 6.7478913 | C13: =C12/30 -> 7.6645233 | D13: =D12/30 -> 8.7080597 | E13: =E12/30 -> 9.8964566 | F13: =F12/30 -> 11.250276 | G13: =G12/30 -> 12.793076 | H13: =H12/30 -> 14.551861 | I13: =I12/30 -> 16.557601 | ... Y13: =Y12/30 -> 128.96979
A14: Pedidos de recompra | B14: =Plan_Supuestos!$D$24*IF(B$4>12,INDEX($B12:$Y12,B$4-12),Plan_Supuestos!$B$7) -> 9.6 | C14: =Plan_Supuestos!$D$24*IF(C$4>12,INDEX($B12:$Y12,C$4-12),Plan_Supuestos!$B$7) -> 9.6 | D14: =Plan_Supuestos!$D$24*IF(D$4>12,INDEX($B12:$Y12,D$4-12),Plan_Supuestos!$B$7) -> 9.6 | E14: =Plan_Supuestos!$D$24*IF(E$4>12,INDEX($B12:$Y12,E$4-12),Plan_Supuestos!$B$7) -> 9.6 | F14: =Plan_Supuestos!$D$24*IF(F$4>12,INDEX($B12:$Y12,F$4-12),Plan_Supuestos!$B$7) -> 9.6 | G14: =Plan_Supuestos!$D$24*IF(G$4>12,INDEX($B12:$Y12,G$4-12),Plan_Supuestos!$B$7) -> 9.6 | H14: =Plan_Supuestos!$D$24*IF(H$4>12,INDEX($B12:$Y12,H$4-12),Plan_Supuestos!$B$7) -> 9.6 | I14: =Plan_Supuestos!$D$24*IF(I$4>12,INDEX($B12:$Y12,I$4-12),Plan_Supuestos!$B$7) -> 9.6 | ... Y14: =Plan_Supuestos!$D$24*IF(Y$4>12,INDEX($B12:$Y12,Y$4-12),Plan_Supuestos!$B$7) -> 133.65526
A15: Pedidos totales | B15: =B12+B14 -> 212.03674 | C15: =C12+C14 -> 239.5357 | D15: =D12+D14 -> 270.84179 | E15: =E12+E14 -> 306.4937 | F15: =F12+F14 -> 347.10828 | G15: =G12+G14 -> 393.39229 | H15: =H12+H14 -> 446.15584 | I15: =I12+I14 -> 506.32803 | ... Y15: =Y12+Y14 -> 4002.7489
A16: Avance de la transicion de mezcla | B16: =MIN(1,(B$4-1)/11) -> 0 | C16: =MIN(1,(C$4-1)/11) -> 0.090909091 | D16: =MIN(1,(D$4-1)/11) -> 0.18181818 | E16: =MIN(1,(E$4-1)/11) -> 0.27272727 | F16: =MIN(1,(F$4-1)/11) -> 0.36363636 | G16: =MIN(1,(G$4-1)/11) -> 0.45454545 | H16: =MIN(1,(H$4-1)/11) -> 0.54545455 | I16: =MIN(1,(I$4-1)/11) -> 0.63636364 | ... Y16: =MIN(1,(Y$4-1)/11) -> 1
